Workbook

Sheet Cleaned_Working
A1: ID | B1: TransactionDates | C1: PaymentsHistory | D1: m1 | E1: m2 | F1: m3 | G1: m4 | H1: m5 | I1: m6 | J1: Total_Future_Repaid | K1: Repaid_Amount_Bucket | L1: Default_Flag | M1: PaSt_Payment_Count | N1: Missed_Payment_Count | O1: Has_Missed_Payment | P1: Total_past_paid | Q1: Pat_avg_payment
A2: ID_O5KG3X6 | B2: ['02-2018', '03-2018', '04-2018', '05-2018', '06-2018', '07-2018', '08-2018', '09-2018', '10-2018', '11-2018', '12-2018', '01-2019', '02-2019', '03-2019', '04-2019', '05-2019', '06-2019', '07-2019', '08-2019', '09-2019', '10-2019', '11-2019', '12-2019', '01-2020', '02-2020'] | C2: [3000.0, 2385.0, 1000.0, 2400.0, 1000.0, 2000.0, 1250.0, 950.0, 460.0, 300.0, 110.0, 105.0, 200.0, 110.0, 210.0, 300.0, 200.0, 650.0, 605.0, 65.0, 100.0, 110.0, 3700.0, 950.0, 1525.0] | D2: 33890 | E2: 900 | F2: 1565 | G2: 1705 | H2: 2015 | I2: 725 | J2: =SUM(D2:I2) -> 40800 | K2: =IFS( J2 <= 2000, "Low (<=2,000$ – Bottom ~25%)", J2 <= 4750, "Medium-Low (2,001–4,750$)", J2 <= 6630, "Medium-High (4,751–6,630$ – Top 50–75%)", TRUE, "High (>6,630$ – Top ~25%)" ) -> High (>6,630$ – Top ~25%) | L2: =IF(J2=0, "Default / High Risk", "Paid Something") -> Paid Something | M2: =IF(C2="", 0, LEN(C2) - LEN(SUBSTITUTE(C2, ",", "")) + 1) -> 25 | N2: =IFERROR(__xludf.DUMMYFUNCTION("IF(C2="""", 0, SUM(ARRAYFORMULA(IF(SPLIT(C2, "","")=""0"", 1, 0))))"),0.0) -> 0 | O2: =IF(C2="", "No History", IF(ISNUMBER(SEARCH(",0.0,", ","&C2&",")) + ISNUMBER(SEARCH(",0.0]", ","&C2&"]")) > 0, "Yes", "No")) -> No | P2: =IFERROR(__xludf.DUMMYFUNCTION("IF(C2="""", 0, SUM( ARRAYFORMULA( IFERROR( VALUE(REGEXREPLACE(TRIM(SPLIT(REGEXREPLACE(C2, ""[\[\]]"", """"), "","")), ""[^0-9.]"", """")), 0 ) ) ) )"),23685.0) -> 23685 | Q2: =IF(M2=0, 0, P2/M2) -> 947.4
A3: ID_1F9H57X | B3: ['04-2018', '05-2018', '06-2018', '07-2018', '08-2018', '09-2018', '10-2018', '11-2018', '12-2018', '01-2019', '02-2019', '03-2019'] | C3: [2500.0, 1860.0, 1530.0, 1400.0, 1500.0, 1650.0, 1650.0, 1650.0, 1400.0, 1850.0, 3605.0, 2660.0] | D3: 33438 | E3: 1540 | F3: 1420 | G3: 1595 | H3: 1375 | I3: 1805 | J3: =SUM(D3:I3) -> 41173 | K3: =IFS( J3 <= 2000, "Low (<=2,000$ – Bottom ~25%)", J3 <= 4750, "Medium-Low (2,001–4,750$)", J3 <= 6630, "Medium-High (4,751–6,630$ – Top 50–75%)", TRUE, "High (>6,630$ – Top ~25%)" ) -> High (>6,630$ – Top ~25%) | L3: =IF(J3=0, "Default / High Risk", "Paid Something") -> Paid Something | M3: =IF(C3="", 0, LEN(C3) - LEN(SUBSTITUTE(C3, ",", "")) + 1) -> 12 | N3: =IFERROR(__xludf.DUMMYFUNCTION("IF(C3="""", 0, SUM(ARRAYFORMULA(IF(SPLIT(C3, "","")=""0"", 1, 0))))"),0.0) -> 0 | O3: =IF(C3="", "No History", IF(ISNUMBER(SEARCH(",0.0,", ","&C3&",")) + ISNUMBER(SEARCH(",0.0]", ","&C3&"]")) > 0, "Yes", "No")) -> No | P3: =IFERROR(__xludf.DUMMYFUNCTION("IF(C3="""", 0, SUM( ARRAYFORMULA( IFERROR( VALUE(REGEXREPLACE(TRIM(SPLIT(REGEXREPLACE(C3, ""[\[\]]"", """"), "","")), ""[^0-9.]"", """")), 0 ) ) ) )"),23255.0) -> 23255 | Q3: =IF(M3=0, 0, P3/M3) -> 1937.9167
A4: ID_KDPEWCO | B4: ['03-2018', '05-2018', '06-2018', '07-2018', '08-2018', '09-2018', '10-2018', '11-2018', '12-2018', '01-2019', '02-2019', '03-2019', '04-2019', '05-2019', '06-2019', '07-2019', '08-2019', '09-2019', '10-2019', '11-2019', '12-2019', '01-2020', '02-2020', '03-2020', '04-2020', '05-2020', '06-2020', '07-2020', '08-2020', '09-2020', '10-2020', '11-2020'] | C4: [8000.0, 300.0, 420.0, 100.0, 400.0, 600.0, 1685.0, 1400.0, 1500.0, 1600.0, 1480.0, 1400.0, 1620.0, 1155.0, 1300.0, 700.0, 810.0, 790.0, 900.0, 1100.0, 800.0, 955.0, 600.0, 700.0, 200.0, 400.0, 400.0, 500.0, 600.0, 1100.0, 2000.0, 1950.0] | D4: 25980 | E4: 950 | F4: 1055 | G4: 1700 | H4: 1400 | I4: 1500 | J4: =SUM(D4:I4) -> 32585 | K4: =IFS( J4 <= 2000, "Low (<=2,000$ – Bottom ~25%)", J4 <= 4750, "Medium-Low (2,001–4,750$)", J4 <= 6630, "Medium-High (4,751–6,630$ – Top 50–75%)", TRUE, "High (>6,630$ – Top ~25%)" ) -> High (>6,630$ – Top ~25%) | L4: =IF(J4=0, "Default / High Risk", "Paid Something") -> Paid Something | M4: =IF(C4="", 0, LEN(C4) - LEN(SUBSTITUTE(C4, ",", "")) + 1) -> 32 | N4: =IFERROR(__xludf.DUMMYFUNCTION("IF(C4="""", 0, SUM(ARRAYFORMULA(IF(SPLIT(C4, "","")=""0"", 1, 0))))"),0.0) -> 0 | O4: =IF(C4="", "No History", IF(ISNUMBER(SEARCH(",0.0,", ","&C4&",")) + ISNUMBER(SEARCH(",0.0]", ","&C4&"]")) > 0, "Yes", "No")) -> No | P4: =IFERROR(__xludf.DUMMYFUNCTION("IF(C4="""", 0, SUM( ARRAYFORMULA( IFERROR( VALUE(REGEXREPLACE(TRIM(SPLIT(REGEXREPLACE(C4, ""[\[\]]"", """"), "","")), ""[^0-9.]"", """")), 0 ) ) ) )"),37465.0) -> 37465 | Q4: =IF(M4=0, 0, P4/M4) -> 1170.7812
A5: ID_UYGBPQT | B5: ['08-2017', '09-2017', '10-2017', '01-2018', '07-2018', '08-2018', '09-2018', '10-2018', '11-2018', '12-2018'] | C5: [12000.0, 6730.0, 3000.0, 3000.0, 2600.0, 2900.0, 2200.0, 3000.0, 4200.0, 1000.0] | D5: 12600 | E5: 9360 | F5: 950 | G5: 2970 | H5: 30450 | I5: 4800 | J5: =SUM(D5:I5) -> 61130 | K5: =IFS( J5 <= 2000, "Low (<=2,000$ – Bottom ~25%)", J5 <= 4750, "Medium-Low (2,001–4,750$)", J5 <= 6630, "Medium-High (4,751–6,630$ – Top 50–75%)", TRUE, "High (>6,630$ – Top ~25%)" ) -> High (>6,630$ – Top ~25%) | L5: =IF(J5=0, "Default / High Risk", "Paid Something") -> Paid Something | M5: =IF(C5="", 0, LEN(C5) - LEN(SUBSTITUTE(C5, ",", "")) + 1) -> 10 | N5: =IFERROR(__xludf.DUMMYFUNCTION("IF(C5="""", 0, SUM(ARRAYFORMULA(IF(SPLIT(C5, "","")=""0"", 1, 0))))"),0.0) -> 0 | O5: =IF(C5="", "No History", IF(ISNUMBER(SEARCH(",0.0,", ","&C5&",")) + ISNUMBER(SEARCH(",0.0]", ","&C5&"]")) > 0, "Yes", "No")) -> No | P5: =IFERROR(__xludf.DUMMYFUNCTION("IF(C5="""", 0, SUM( ARRAYFORMULA( IFERROR( VALUE(REGEXREPLACE(TRIM(SPLIT(REGEXREPLACE(C5, ""[\[\]]"", """"), "","")), ""[^0-9.]"", """")), 0 ) ) ) )"),40630.0) -> 40630 | Q5: =IF(M5=0, 0, P5/M5) -> 4063
A6: ID_GVW7LEP | B6: ['04-2018', '05-2018', '06-2018', '07-2018', '08-2018', '09-2018', '10-2018', '11-2018', '12-2018', '01-2019', '02-2019', '03-2019', '04-2019', '05-2019', '06-2019', '07-2019', '08-2019', '09-2019'] | C6: [2775.0, 1320.0, 1540.0, 990.0, 1155.0, 1155.0, 1155.0, 770.0, 1045.0, 550.0, 715.0, 660.0, 650.0, 990.0, 935.0, 935.0, 1100.0, 2055.0] | D6: 9950 | E6: 605 | F6: 605 | G6: 535 | H6: 585 | I6: 305 | J6: =SUM(D6:I6) -> 12585 | K6: =IFS( J6 <= 2000, "Low (<=2,000$ – Bottom ~25%)", J6 <= 4750, "Medium-Low (2,001–4,750$)", J6 <= 6630, "Medium-High (4,751–6,630$ – Top 50–75%)", TRUE, "High (>6,630$ – Top ~25%)" ) -> High (>6,630$ – Top ~25%) | L6: =IF(J6=0, "Default / High Risk", "Paid Something") -> Paid Something | M6: =IF(C6="", 0, LEN(C6) - LEN(SUBSTITUTE(C6, ",", "")) + 1) -> 18 | N6: =IFERROR(__xludf.DUMMYFUNCTION("IF(C6="""", 0, SUM(ARRAYFORMULA(IF(SPLIT(C6, "","")=""0"", 1, 0))))"),0.0) -> 0 | O6: =IF(C6="", "No History", IF(ISNUMBER(SEARCH(",0.0,", ","&C6&",")) + ISNUMBER(SEARCH(",0.0]", ","&C6&"]")) > 0, "Yes", "No")) -> No | P6: =IFERROR(__xludf.DUMMYFUNCTION("IF(C6="""", 0, SUM( ARRAYFORMULA( IFERROR( VALUE(REGEXREPLACE(TRIM(SPLIT(REGEXREPLACE(C6, ""[\[\]]"", """"), "","")), ""[^0-9.]"", """")), 0 ) ) ) )"),20495.0) -> 20495 | Q6: =IF(M6=0, 0, P6/M6) -> 1138.6111
A7: ID_UOJ52DX | B7: ['03-2018', '04-2018', '05-2018', '06-2018', '07-2018', '08-2018', '09-2018', '12-2018', '01-2019', '02-2019'] | C7: [8599.0, 3485.0, 3000.0, 1300.0, 100.0, 215.0, 205.0, 110.0, 1410.0, 1000.0] | D7: 8760 | E7: 255 | F7: 1100 | G7: 1205 | H7: 1270 | I7: 1070 | J7: =SUM(D7:I7) -> 13660 | K7: =IFS( J7 <= 2000, "Low (<=2,000$ – Bottom ~25%)", J7 <= 4750, "Medium-Low (2,001–4,750$)", J7 <= 6630, "Medium-High (4,751–6,630$ – Top 50–75%)", TRUE, "High (>6,630$ – Top ~25%)" ) -> High (>6,630$ – Top ~25%) | L7: =IF(J7=0, "Default / High Risk", "Paid Something") -> Paid Something | M7: =IF(C7="", 0, LEN(C7) - LEN(SUBSTITUTE(C7, ",", "")) + 1) -> 10 | N7: =IFERROR(__xludf.DUMMYFUNCTION("IF(C7="""", 0, SUM(ARRAYFORMULA(IF(SPLIT(C7, "","")=""0"", 1, 0))))"),0.0) -> 0 | O7: =IF(C7="", "No History", IF(ISNUMBER(SEARCH(",0.0,", ","&C7&",")) + ISNUMBER(SEARCH(",0.0]", ","&C7&"]")) > 0, "Yes", "No")) -> No | P7: =IFERROR(__xludf.DUMMYFUNCTION("IF(C7="""", 0, SUM( ARRAYFORMULA( IFERROR( VALUE(REGEXREPLACE(TRIM(SPLIT(REGEXREPLACE(C7, ""[\[\]]"", """"), "","")), ""[^0-9.]"", """")), 0 ) ) ) )"),19424.0) -> 19424 | Q7: =IF(M7=0, 0, P7/M7) -> 1942.4
A8: ID_ZYLVKN0 | B8: ['04-2018', '05-2018', '09-2018', '10-2018', '11-2018', '12-2018', '01-2019', '02-2019', '03-2019', '05-2019'] | C8: [3000.0, 4500.0, 400.0, 750.0, 350.0, 2200.0, 1270.0, 2000.0, 3310.0, 800.0] | D8: 8550 | E8: 1200 | F8: 1490 | G8: 1347 | H8: 863 | I8: 1050 | J8: =SUM(D8:I8) -> 14500 | K8: =IFS( J8 <= 2000, "Low (<=2,000$ – Bottom ~25%)", J8 <= 4750, "Medium-Low (2,001–4,750$)", J8 <= 6630, "Medium-High (4,751–6,630$ – Top 50–75%)", TRUE, "High (>6,630$ – Top ~25%)" ) -> High (>6,630$ – Top ~25%) | L8: =IF(J8=0, "Default / High Risk", "Paid Something") -> Paid Something | M8: =IF(C8="", 0, LEN(C8) - LEN(SUBSTITUTE(C8, ",", "")) + 1) -> 10 | N8: =IFERROR(__xludf.DUMMYFUNCTION("IF(C8="""", 0, SUM(ARRAYFORMULA(IF(SPLIT(C8, "","")=""0"", 1, 0))))"),0.0) -> 0 | O8: =IF(C8="", "No History", IF(ISNUMBER(SEARCH(",0.0,", ","&C8&",")) + ISNUMBER(SEARCH(",0.0]", ","&C8&"]")) > 0, "Yes", "No")) -> No | P8: =IFERROR(__xludf.DUMMYFUNCTION("IF(C8="""", 0, SUM( ARRAYFORMULA( IFERROR( VALUE(REGEXREPLACE(TRIM(SPLIT(REGEXREPLACE(C8, ""[\[\]]"", """"), "","")), ""[^0-9.]"", """")), 0 ) ) ) )"),18580.0) -> 18580 | Q8: =IF(M8=0, 0, P8/M8) -> 1858
A9: ID_RA4PSAL | B9: ['03-2018', '05-2018', '06-2018', '07-2018', '08-2018', '09-2018', '10-2018', '11-2018', '12-2018', '01-2019'] | C9: [5000.0, 1500.0, 2555.0, 2000.0, 1000.0, 250.0, 860.0, 1650.0, 1320.0, 1510.0] | D9: 8100 | E9: 1310 | F9: 1365 | G9: 1810 | H9: 1215 | I9: 1585 | J9: =SUM(D9:I9) -> 15385 | K9: =IFS( J9 <= 2000, "Low (<=2,000$ – Bottom ~25%)", J9 <= 4750, "Medium-Low (2,001–4,750$)", J9 <= 6630, "Medium-High (4,751–6,630$ – Top 50–75%)", TRUE, "High (>6,630$ – Top ~25%)" ) -> High (>6,630$ – Top ~25%) | L9: =IF(J9=0, "Default / High Risk", "Paid Something") -> Paid Something | M9: =IF(C9="", 0, LEN(C9) - LEN(SUBSTITUTE(C9, ",", "")) + 1) -> 10 | N9: =IFERROR(__xludf.DUMMYFUNCTION("IF(C9="""", 0, SUM(ARRAYFORMULA(IF(SPLIT(C9, "","")=""0"", 1, 0))))"),0.0) -> 0 | O9: =IF(C9="", "No History", IF(ISNUMBER(SEARCH(",0.0,", ","&C9&",")) + ISNUMBER(SEARCH(",0.0]", ","&C9&"]")) > 0, "Yes", "No")) -> No | P9: =IFERROR(__xludf.DUMMYFUNCTION("IF(C9="""", 0, SUM( ARRAYFORMULA( IFERROR( VALUE(REGEXREPLACE(TRIM(SPLIT(REGEXREPLACE(C9, ""[\[\]]"", """"), "","")), ""[^0-9.]"", """")), 0 ) ) ) )"),17645.0) -> 17645 | Q9: =IF(M9=0, 0, P9/M9) -> 1764.5
A10: ID_BRR6P6W | B10: ['02-2018', '05-2018', '07-2018', '08-2018', '09-2018', '10-2018'] | C10: [13000.0, 1650.0, 2850.0, 2850.0, 1400.0, 8900.0] | D10: 7800 | E10: 5000 | F10: 5000 | G10: 3000 | H10: 3000 | I10: 2514 | J10: =SUM(D10:I10) -> 26314 | K10: =IFS( J10 <= 2000, "Low (<=2,000$ – Bottom ~25%)", J10 <= 4750, "Medium-Low (2,001–4,750$)", J10 <= 6630, "Medium-High (4,751–6,630$ – Top 50–75%)", TRUE, "High (>6,630$ – Top ~25%)" ) -> High (>6,630$ – Top ~25%) | L10: =IF(J10=0, "Default / High Risk", "Paid Something") -> Paid Something | M10: =IF(C10="", 0, LEN(C10) - LEN(SUBSTITUTE(C10, ",", "")) + 1) -> 6 | N10: =IFERROR(__xludf.DUMMYFUNCTION("IF(C10="""", 0, SUM(ARRAYFORMULA(IF(SPLIT(C10, "","")=""0"", 1, 0))))"),0.0) -> 0 | O10: =IF(C10="", "No History", IF(ISNUMBER(SEARCH(",0.0,", ","&C10&",")) + ISNUMBER(SEARCH(",0.0]", ","&C10&"]")) > 0, "Yes", "No")) -> No | P10: =IFERROR(__xludf.DUMMYFUNCTION("IF(C10="""", 0, SUM( ARRAYFORMULA( IFERROR( VALUE(REGEXREPLACE(TRIM(SPLIT(REGEXREPLACE(C10, ""[\[\]]"", """"), "","")), ""[^0-9.]"", """")), 0 ) ) ) )"),30650.0) -> 30650 | Q10: =IF(M10=0, 0, P10/M10) -> 5108.3333
A11: ID_ET5313E | B11: ['02-2018', '03-2018', '04-2018', '05-2018', '07-2018'] | C11: [3000.0, 4950.0, 3300.0, 1650.0, 2235.0] | D11: 6650 | E11: 4950 | F11: 1100 | G11: 2100 | H11: 2149 | I11: 1000 | J11: =SUM(D11:I11) -> 17949 | K11: =IFS( J11 <= 2000, "Low (<=2,000$ – Bottom ~25%)", J11 <= 4750, "Medium-Low (2,001–4,750$)", J11 <= 6630, "Medium-High (4,751–6,630$ – Top 50–75%)", TRUE, "High (>6,630$ – Top ~25%)" ) -> High (>6,630$ – Top ~25%) | L11: =IF(J11=0, "Default / High Risk", "Paid Something") -> Paid Something | M11: =IF(C11="", 0, LEN(C11) - LEN(SUBSTITUTE(C11, ",", "")) + 1) -> 5 | N11: =IFERROR(__xludf.DUMMYFUNCTION("IF(C11="""", 0, SUM(ARRAYFORMULA(IF(SPLIT(C11, "","")=""0"", 1, 0))))"),0.0) -> 0 | O11: =IF(C11="", "No History", IF(ISNUMBER(SEARCH(",0.0,", ","&C11&",")) + ISNUMBER(SEARCH(",0.0]", ","&C11&"]")) > 0, "Yes", "No")) -> No | P11: =IFERROR(__xludf.DUMMYFUNCTION("IF(C11="""", 0, SUM( ARRAYFORMULA( IFERROR( VALUE(REGEXREPLACE(TRIM(SPLIT(REGEXREPLACE(C11, ""[\[\]]"", """"), "","")), ""[^0-9.]"", """")), 0 ) ) ) )"),15135.0) -> 15135 | Q11: =IF(M11=0, 0, P11/M11) -> 3027
A12: ID_GLD0EES | B12: ['02-2018', '03-2018', '04-2018', '08-2018', '10-2018', '11-2018'] | C12: [13000.0, 10000.0, 5000.0, 5000.0, 4000.0, 4000.0] | D12: 6000 | E12: 2400 | F12: 1055 | G12: 3900 | H12: 1500 | I12: 1109 | J12: =SUM(D12:I12) -> 15964 | K12: =IFS( J12 <= 2000, "Low (<=2,000$ – Bottom ~25%)", J12 <= 4750, "Medium-Low (2,001–4,750$)", J12 <= 6630, "Medium-High (4,751–6,630$ – Top 50–75%)", TRUE, "High (>6,630$ – Top ~25%)" ) -> High (>6,630$ – Top ~25%) | L12: =IF(J12=0, "Default / High Risk", "Paid Something") -> Paid Something | M12: =IF(C12="", 0, LEN(C12) - LEN(SUBSTITUTE(C12, ",", "")) + 1) -> 6 | N12: =IFERROR(__xludf.DUMMYFUNCTION("IF(C12="""", 0, SUM(ARRAYFORMULA(IF(SPLIT(C12, "","")=""0"", 1, 0))))"),0.0) -> 0 | O12: =IF(C12="", "No History", IF(ISNUMBER(SEARCH(",0.0,", ","&C12&",")) + ISNUMBER(SEARCH(",0.0]", ","&C12&"]")) > 0, "Yes", "No")) -> No | P12: =IFERROR(__xludf.DUMMYFUNCTION("IF(C12="""", 0, SUM( ARRAYFORMULA( IFERROR( VALUE(REGEXREPLACE(TRIM(SPLIT(REGEXREPLACE(C12, ""[\[\]]"", """"), "","")), ""[^0-9.]"", """")), 0 ) ) ) )"),41000.0) -> 41000 | Q12: =IF(M12=0, 0, P12/M12) -> 6833.3333
A13: ID_L561HVU | B13: ['03-2018', '04-2018', '05-2018', '06-2018', '07-2018', '08-2018', '09-2018', '10-2018', '11-2018'] | C13: [7500.0, 2900.0, 3000.0, 1900.0, 3500.0, 3000.0, 3000.0, 3000.0, 3000.0] | D13: 6000 | E13: 3000 | F13: 3200 | G13: 3000 | H13: 3100 | I13: 7864 | J13: =SUM(D13:I13) -> 26164 | K13: =IFS( J13 <= 2000, "Low (<=2,000$ – Bottom ~25%)", J13 <= 4750, "Medium-Low (2,001–4,750$)", J13 <= 6630, "Medium-High (4,751–6,630$ – Top 50–75%)", TRUE, "High (>6,630$ – Top ~25%)" ) -> High (>6,630$ – Top ~25%) | L13: =IF(J13=0, "Default / High Risk", "Paid Something") -> Paid Something | M13: =IF(C13="", 0, LEN(C13) - LEN(SUBSTITUTE(C13, ",", "")) + 1) -> 9 | N13: =IFERROR(__xludf.DUMMYFUNCTION("IF(C13="""", 0, SUM(ARRAYFORMULA(IF(SPLIT(C13, "","")=""0"", 1, 0))))"),0.0) -> 0 | O13: =IF(C13="", "No History", IF(ISNUMBER(SEARCH(",0.0,", ","&C13&",")) + ISNUMBER(SEARCH(",0.0]", ","&C13&"]")) > 0, "Yes", "No")) -> No | P13: =IFERROR(__xludf.DUMMYFUNCTION("IF(C13="""", 0, SUM( ARRAYFORMULA( IFERROR( VALUE(REGEXREPLACE(TRIM(SPLIT(REGEXREPLACE(C13, ""[\[\]]"", """"), "","")), ""[^0-9.]"", """")), 0 ) ) ) )"),30800.0) -> 30800 | Q13: =IF(M13=0, 0, P13/M13) -> 3422.2222
A14: ID_FTV8FZJ | B14: ['04-2018', '05-2018', '06-2018', '07-2018', '09-2018', '11-2018', '01-2019'] | C14: [2885.0, 500.0, 550.0, 1650.0, 2000.0, 2000.0, 4000.0] | D14: 6000 | E14: 4000 | F14: 2000 | G14: 2000 | H14: 2000 | I14: 3495 | J14: =SUM(D14:I14) -> 19495 | K14: =IFS( J14 <= 2000, "Low (<=2,000$ – Bottom ~25%)", J14 <= 4750, "Medium-Low (2,001–4,750$)", J14 <= 6630, "Medium-High (4,751–6,630$ – Top 50–75%)", TRUE, "High (>6,630$ – Top ~25%)" ) -> High (>6,630$ – Top ~25%) | L14: =IF(J14=0, "Default / High Risk", "Paid Something") -> Paid Something | M14: =IF(C14="", 0, LEN(C14) - LEN(SUBSTITUTE(C14, ",", "")) + 1) -> 7 | N14: =IFERROR(__xludf.DUMMYFUNCTION("IF(C14="""", 0, SUM(ARRAYFORMULA(IF(SPLIT(C14, "","")=""0"", 1, 0))))"),0.0) -> 0 | O14: =IF(C14="", "No History", IF(ISNUMBER(SEARCH(",0.0,", ","&C14&",")) + ISNUMBER(SEARCH(",0.0]", ","&C14&"]")) > 0, "Yes", "No")) -> No | P14: =IFERROR(__xludf.DUMMYFUNCTION("IF(C14="""", 0, SUM( ARRAYFORMULA( IFERROR( VALUE(REGEXREPLACE(TRIM(SPLIT(REGEXREPLACE(C14, ""[\[\]]"", """"), "","")), ""[^0-9.]"", """")), 0 ) ) ) )"),13585.0) -> 13585 | Q14: =IF(M14=0, 0, P14/M14) -> 1940.7143
A15: ID_GAIAFV3 | B15: ['02-2018', '03-2018', '04-2018', '05-2018', '06-2018', '07-2018', '08-2018', '09-2018', '10-2018', '11-2018', '12-2018', '01-2019', '02-2019'] | C15: [4055.0, 1400.0, 1400.0, 1800.0, 1550.0, 1700.0, 1300.0, 2000.0, 2000.0, 2000.0, 700.0, 1700.0, 950.0] | D15: 6000 | E15: 500 | F15: 1000 | G15: 500 | H15: 1950 | I15: 1000 | J15: =SUM(D15:I15) -> 10950 | K15: =IFS( J15 <= 2000, "Low (<=2,000$ – Bottom ~25%)", J15 <= 4750, "Medium-Low (2,001–4,750$)", J15 <= 6630, "Medium-High (4,751–6,630$ – Top 50–75%)", TRUE, "High (>6,630$ – Top ~25%)" ) -> High (>6,630$ – Top ~25%) | L15: =IF(J15=0, "Default / High Risk", "Paid Something") -> Paid Something | M15: =IF(C15="", 0, LEN(C15) - LEN(SUBSTITUTE(C15, ",", "")) + 1) -> 13 | N15: =IFERROR(__xludf.DUMMYFUNCTION("IF(C15="""", 0, SUM(ARRAYFORMULA(IF(SPLIT(C15, "","")=""0"", 1, 0))))"),0.0) -> 0 | O15: =IF(C15="", "No History", IF(ISNUMBER(SEARCH(",0.0,", ","&C15&",")) + ISNUMBER(SEARCH(",0.0]", ","&C15&"]")) > 0, "Yes", "No")) -> No | P15: =IFERROR(__xludf.DUMMYFUNCTION("IF(C15="""", 0, SUM( ARRAYFORMULA( IFERROR( VALUE(REGEXREPLACE(TRIM(SPLIT(REGEXREPLACE(C15, ""[\[\]]"", """"), "","")), ""[^0-9.]"", """")), 0 ) ) ) )"),22555.0) -> 22555 | Q15: =IF(M15=0, 0, P15/M15) -> 1735
A16: ID_12QBNP0 | B16: ['04-2018', '06-2018', '07-2018', '08-2018', '09-2018', '10-2018', '11-2018', '01-2019', '02-2019', '03-2019', '05-2019', '06-2019', '07-2019', '08-2019', '10-2019'] | C16: [8000.0, 2850.0, 385.0, 380.0, 665.0, 190.0, 2850.0, 665.0, 190.0, 2850.0, 2850.0, 2850.0, 2850.0, 2850.0, 5795.0] | D16: 5700 | E16: 2850 | F16: 3230 | G16: 2850 | H16: 3600 | I16: 3084 | J16: =SUM(D16:I16) -> 21314 | K16: =IFS( J16 <= 2000, "Low (<=2,000$ – Bottom ~25%)", J16 <= 4750, "Medium-Low (2,001–4,750$)", J16 <= 6630, "Medium-High (4,751–6,630$ – Top 50–75%)", TRUE, "High (>6,630$ – Top ~25%)" ) -> High (>6,630$ – Top ~25%) | L16: =IF(J16=0, "Default / High Risk", "Paid Something") -> Paid Something | M16: =IF(C16="", 0, LEN(C16) - LEN(SUBSTITUTE(C16, ",", "")) + 1) -> 15 | N16: =IFERROR(__xludf.DUMMYFUNCTION("IF(C16="""", 0, SUM(ARRAYFORMULA(IF(SPLIT(C16, "","")=""0"", 1, 0))))"),0.0) -> 0 | O16: =IF(C16="", "No History", IF(ISNUMBER(SEARCH(",0.0,", ","&C16&",")) + ISNUMBER(SEARCH(",0.0]", ","&C16&"]")) > 0, "Yes", "No")) -> No | P16: =IFERROR(__xludf.DUMMYFUNCTION("IF(C16="""", 0, SUM( ARRAYFORMULA( IFERROR( VALUE(REGEXREPLACE(TRIM(SPLIT(REGEXREPLACE(C16, ""[\[\]]"", """"), "","")), ""[^0-9.]"", """")), 0 ) ) ) )"),36220.0) -> 36220 | Q16: =IF(M16=0, 0, P16/M16) -> 2414.6667
A17: ID_8MFTNJ8 | B17: ['03-2018', '04-2018', '05-2018', '08-2018', '09-2018', '10-2018', '11-2018', '12-2018', '01-2019', '02-2019'] | C17: [7620.0, 2850.0, 2850.0, 2850.0, 2850.0, 2850.0, 2850.0, 2850.0, 2850.0, 2850.0] | D17: 5700 | E17: 2050 | F17: 3069 | G17: 6138 | H17: 3069 | I17: 3668 | J17: =SUM(D17:I17) -> 23694 | K17: =IFS( J17 <= 2000, "Low (<=2,000$ – Bottom ~25%)", J17 <= 4750, "Medium-Low (2,001–4,750$)", J17 <= 6630, "Medium-High (4,751–6,630$ – Top 50–75%)", TRUE, "High (>6,630$ – Top ~25%)" ) -> High (>6,630$ – Top ~25%) | L17: =IF(J17=0, "Default / High Risk", "Paid Something") -> Paid Something | M17: =IF(C17="", 0, LEN(C17) - LEN(SUBSTITUTE(C17, ",", "")) + 1) -> 10 | N17: =IFERROR(__xludf.DUMMYFUNCTION("IF(C17="""", 0, SUM(ARRAYFORMULA(IF(SPLIT(C17, "","")=""0"", 1, 0))))"),0.0) -> 0 | O17: =IF(C17="", "No History", IF(ISNUMBER(SEARCH(",0.0,", ","&C17&",")) + ISNUMBER(SEARCH(",0.0]", ","&C17&"]")) > 0, "Yes", "No")) -> No | P17: =IFERROR(__xludf.DUMMYFUNCTION("IF(C17="""", 0, SUM( ARRAYFORMULA( IFERROR( VALUE(REGEXREPLACE(TRIM(SPLIT(REGEXREPLACE(C17, ""[\[\]]"", """"), "","")), ""[^0-9.]"", """")), 0 ) ) ) )"),33270.0) -> 33270 | Q17: =IF(M17=0, 0, P17/M17) -> 3327
A18: ID_F63EKBS | B18: ['02-2018', '03-2018', '04-2018', '05-2018', '06-2018'] | C18: [3340.0, 400.0, 2000.0, 245.0, 1355.0] | D18: 5525 | E18: 5000 | F18: 1000 | G18: 1150 | H18: 1700 | I18: 12000 | J18: =SUM(D18:I18) -> 26375 | K18: =IFS( J18 <= 2000, "Low (<=2,000$ – Bottom ~25%)", J18 <= 4750, "Medium-Low (2,001–4,750$)", J18 <= 6630, "Medium-High (4,751–6,630$ – Top 50–75%)", TRUE, "High (>6,630$ – Top ~25%)" ) -> High (>6,630$ – Top ~25%) | L18: =IF(J18=0, "Default / High Risk", "Paid Something") -> Paid Something | M18: =IF(C18="", 0, LEN(C18) - LEN(SUBSTITUTE(C18, ",", "")) + 1) -> 5 | N18: =IFERROR(__xludf.DUMMYFUNCTION("IF(C18="""", 0, SUM(ARRAYFORMULA(IF(SPLIT(C18, "","")=""0"", 1, 0))))"),0.0) -> 0 | O18: =IF(C18="", "No History", IF(ISNUMBER(SEARCH(",0.0,", ","&C18&",")) + ISNUMBER(SEARCH(",0.0]", ","&C18&"]")) > 0, "Yes", "No")) -> No | P18: =IFERROR(__xludf.DUMMYFUNCTION("IF(C18="""", 0, SUM( ARRAYFORMULA( IFERROR( VALUE(REGEXREPLACE(TRIM(SPLIT(REGEXREPLACE(C18, ""[\[\]]"", """"), "","")), ""[^0-9.]"", """")), 0 ) ) ) )"),7340.0) -> 7340 | Q18: =IF(M18=0, 0, P18/M18) -> 1468
A19: ID_TP5ME1R | B19: ['04-2018', '07-2018', '08-2018', '09-2018', '10-2018', '12-2018', '01-2019', '03-2019', '04-2019', '05-2019'] | C19: [6350.0, 1815.0, 550.0, 55.0, 1660.0, 440.0, 2210.0, 1010.0, 820.0, 2220.0] | D19: 5500 | E19: 785 | F19: 775 | G19: 1950 | H19: 1000 | I19: 6000 | J19: =SUM(D19:I19) -> 16010 | K19: =IFS( J19 <= 2000, "Low (<=2,000$ – Bottom ~25%)", J19 <= 4750, "Medium-Low (2,001–4,750$)", J19 <= 6630, "Medium-High (4,751–6,630$ – Top 50–75%)", TRUE, "High (>6,630$ – Top ~25%)" ) -> High (>6,630$ – Top ~25%) | L19: =IF(J19=0, "Default / High Risk", "Paid Something") -> Paid Something | M19: =IF(C19="", 0, LEN(C19) - LEN(SUBSTITUTE(C19, ",", "")) + 1) -> 10 | N19: =IFERROR(__xludf.DUMMYFUNCTION("IF(C19="""", 0, SUM(ARRAYFORMULA(IF(SPLIT(C19, "","")=""0"", 1, 0))))"),0.0) -> 0 | O19: =IF(C19="", "No History", IF(ISNUMBER(SEARCH(",0.0,", ","&C19&",")) + ISNUMBER(SEARCH(",0.0]", ","&C19&"]")) > 0, "Yes", "No")) -> No | P19: =IFERROR(__xludf.DUMMYFUNCTION("IF(C19="""", 0, SUM( ARRAYFORMULA( IFERROR( VALUE(REGEXREPLACE(TRIM(SPLIT(REGEXREPLACE(C19, ""[\[\]]"", """"), "","")), ""[^0-9.]"", """")), 0 ) ) ) )"),17130.0) -> 17130 | Q19: =IF(M19=0, 0, P19/M19) -> 1713
A20: ID_2D7YVBC | B20: ['04-2018', '05-2018', '06-2018', '07-2018', '08-2018', '09-2018', '10-2018', '11-2018', '12-2018', '01-2019', '02-2019', '03-2019', '04-2019', '05-2019', '06-2019', '07-2019', '08-2019', '09-2019', '10-2019', '11-2019', '12-2019', '01-2020', '02-2020', '03-2020', '04-2020'] | C20: [7520.0, 1735.0, 2165.0, 1775.0, 1335.0, 2210.0, 1360.0, 1685.0, 1700.0, 770.0, 1080.0, 950.0, 970.0, 1560.0, 855.0, 1470.0, 1145.0, 738.0, 1045.0, 1140.0, 1710.0, 460.0, 855.0, 840.0, 2530.0] | D20: 5436 | E20: 4141 | F20: 500 | G20: 2080 | H20: 2975 | I20: 2609 | J20: =SUM(D20:I20) -> 17741 | K20: =IFS( J20 <= 2000, "Low (<=2,000$ – Bottom ~25%)", J20 <= 4750, "Medium-Low (2,001–4,750$)", J20 <= 6630, "Medium-High (4,751–6,630$ – Top 50–75%)", TRUE, "High (>6,630$ – Top ~25%)" ) -> High (>6,630$ – Top ~25%) | L20: =IF(J20=0, "Default / High Risk", "Paid Something") -> Paid Something | M20: =IF(C20="", 0, LEN(C20) - LEN(SUBSTITUTE(C20, ",", "")) + 1) -> 25 | N20: =IFERROR(__xludf.DUMMYFUNCTION("IF(C20="""", 0, SUM(ARRAYFORMULA(IF(SPLIT(C20, "","")=""0"", 1, 0))))"),0.0) -> 0 | O20: =IF(C20="", "No History", IF(ISNUMBER(SEARCH(",0.0,", ","&C20&",")) + ISNUMBER(SEARCH(",0.0]", ","&C20&"]")) > 0, "Yes", "No")) -> No | P20: =IFERROR(__xludf.DUMMYFUNCTION("IF(C20="""", 0, SUM( ARRAYFORMULA( IFERROR( VALUE(REGEXREPLACE(TRIM(SPLIT(REGEXREPLACE(C20, ""[\[\]]"", """"), "","")), ""[^0-9.]"", """")), 0 ) ) ) )"),39603.0) -> 39603 | Q20: =IF(M20=0, 0, P20/M20) -> 1584.12
A21: ID_4YKKTRO | B21: ['02-2018', '03-2018', '04-2018', '05-2018', '06-2018', '07-2018', '08-2018', '09-2018', '10-2018', '11-2018', '12-2018', '01-2019', '02-2019', '03-2019'] | C21: [6500.0, 3100.0, 1895.0, 2900.0, 3005.0, 2810.0, 2980.0, 1760.0, 2580.0, 2000.0, 2700.0, 2450.0, 2050.0, 1600.0] | D21: 5195 | E21: 2500 | F21: 2800 | G21: 3100 | H21: 2900 | I21: 2139 | J21: =SUM(D21:I21) -> 18634 | K21: =IFS( J21 <= 2000, "Low (<=2,000$ – Bottom ~25%)", J21 <= 4750, "Medium-Low (2,001–4,750$)", J21 <= 6630, "Medium-High (4,751–6,630$ – Top 50–75%)", TRUE, "High (>6,630$ – Top ~25%)" ) -> High (>6,630$ – Top ~25%) | L21: =IF(J21=0, "Default / High Risk", "Paid Something") -> Paid Something | M21: =IF(C21="", 0, LEN(C21) - LEN(SUBSTITUTE(C21, ",", "")) + 1) -> 14 | N21: =IFERROR(__xludf.DUMMYFUNCTION("IF(C21="""", 0, SUM(ARRAYFORMULA(IF(SPLIT(C21, "","")=""0"", 1, 0))))"),0.0) -> 0 | O21: =IF(C21="", "No History", IF(ISNUMBER(SEARCH(",0.0,", ","&C21&",")) + ISNUMBER(SEARCH(",0.0]", ","&C21&"]")) > 0, "Yes", "No")) -> No | P21: =IFERROR(__xludf.DUMMYFUNCTION("IF(C21="""", 0, SUM( ARRAYFORMULA( IFERROR( VALUE(REGEXREPLACE(TRIM(SPLIT(REGEXREPLACE(C21, ""[\[\]]"", """"), "","")), ""[^0-9.]"", """")), 0 ) ) ) )"),38330.0) -> 38330 | Q21: =IF(M21=0, 0, P21/M21) -> 2737.8571
A22: ID_I1UCVI5 | B22: ['03-2018', '04-2018', '06-2018', '08-2018', '09-2018', '10-2018'] | C22: [4115.0, 3600.0, 4800.0, 3000.0, 830.0, 3800.0] | D22: 5000 | E22: 3000 | F22: 3000 | G22: 1500 | H22: 300 | I22: 139 | J22: =SUM(D22:I22) -> 12939 | K22: =IFS( J22 <= 2000, "Low (<=2,000$ – Bottom ~25%)", J22 <= 4750, "Medium-Low (2,001–4,750$)", J22 <= 6630, "Medium-High (4,751–6,630$ – Top 50–75%)", TRUE, "High (>6,630$ – Top ~25%)" ) -> High (>6,630$ – Top ~25%) | L22: =IF(J22=0, "Default / High Risk", "Paid Something") -> Paid Something | M22: =IF(C22="", 0, LEN(C22) - LEN(SUBSTITUTE(C22, ",", "")) + 1) -> 6 | N22: =IFERROR(__xludf.DUMMYFUNCTION("IF(C22="""", 0, SUM(ARRAYFORMULA(IF(SPLIT(C22, "","")=""0"", 1, 0))))"),0.0) -> 0 | O22: =IF(C22="", "No History", IF(ISNUMBER(SEARCH(",0.0,", ","&C22&",")) + ISNUMBER(SEARCH(",0.0]", ","&C22&"]")) > 0, "Yes", "No")) -> No | P22: =IFERROR(__xludf.DUMMYFUNCTION("IF(C22="""", 0, SUM( ARRAYFORMULA( IFERROR( VALUE(REGEXREPLACE(TRIM(SPLIT(REGEXREPLACE(C22, ""[\[\]]"", """"), "","")), ""[^0-9.]"", """")), 0 ) ) ) )"),20145.0) -> 20145 | Q22: =IF(M22=0, 0, P22/M22) -> 3357.5
A23: ID_1RS6KSO | B23: ['04-2018', '05-2018', '06-2018', '07-2018', '08-2018', '09-2018', '10-2018', '11-2018'] | C23: [4600.0, 1230.0, 2000.0, 2000.0, 2100.0, 1000.0, 2000.0, 1110.0] | D23: 5000 | E23: 1050 | F23: 2050 | G23: 1420 | H23: 3550 | I23: 3970 | J23: =SUM(D23:I23) -> 17040 | K23: =IFS( J23 <= 2000, "Low (<=2,000$ – Bottom ~25%)", J23 <= 4750, "Medium-Low (2,001–4,750$)", J23 <= 6630, "Medium-High (4,751–6,630$ – Top 50–75%)", TRUE, "High (>6,630$ – Top ~25%)" ) -> High (>6,630$ – Top ~25%) | L23: =IF(J23=0, "Default / High Risk", "Paid Something") -> Paid Something | M23: =IF(C23="", 0, LEN(C23) - LEN(SUBSTITUTE(C23, ",", "")) + 1) -> 8 | N23: =IFERROR(__xludf.DUMMYFUNCTION("IF(C23="""", 0, SUM(ARRAYFORMULA(IF(SPLIT(C23, "","")=""0"", 1, 0))))"),0.0) -> 0 | O23: =IF(C23="", "No History", IF(ISNUMBER(SEARCH(",0.0,", ","&C23&",")) + ISNUMBER(SEARCH(",0.0]", ","&C23&"]")) > 0, "Yes", "No")) -> No | P23: =IFERROR(__xludf.DUMMYFUNCTION("IF(C23="""", 0, SUM( ARRAYFORMULA( IFERROR( VALUE(REGEXREPLACE(TRIM(SPLIT(REGEXREPLACE(C23, ""[\[\]]"", """"), "","")), ""[^0-9.]"", """")), 0 ) ) ) )"),16040.0) -> 16040 | Q23: =IF(M23=0, 0, P23/M23) -> 2005
A24: ID_4J1S2E5 | B24: ['02-2018', '03-2018', '04-2018', '05-2018', '06-2018', '07-2018'] | C24: [4500.0, 1500.0, 2000.0, 2000.0, 2000.0, 2000.0] | D24: 5000 | E24: 2000 | F24: 1000 | G24: 10185 | H24: 200 | I24: 699 | J24: =SUM(D24:I24) -> 19084 | K24: =IFS( J24 <= 2000, "Low (<=2,000$ – Bottom ~25%)", J24 <= 4750, "Medium-Low (2,001–4,750$)", J24 <= 6630, "Medium-High (4,751–6,630$ – Top 50–75%)", TRUE, "High (>6,630$ – Top ~25%)" ) -> High (>6,630$ – Top ~25%) | L24: =IF(J24=0, "Default / High Risk", "Paid Something") -> Paid Something | M24: =IF(C24="", 0, LEN(C24) - LEN(SUBSTITUTE(C24, ",", "")) + 1) -> 6 | N24: =IFERROR(__xludf.DUMMYFUNCTION("IF(C24="""", 0, SUM(ARRAYFORMULA(IF(SPLIT(C24, "","")=""0"", 1, 0))))"),0.0) -> 0 | O24: =IF(C24="", "No History", IF(ISNUMBER(SEARCH(",0.0,", ","&C24&",")) + ISNUMBER(SEARCH(",0.0]", ","&C24&"]")) > 0, "Yes", "No")) -> No | P24: =IFERROR(__xludf.DUMMYFUNCTION("IF(C24="""", 0, SUM( ARRAYFORMULA( IFERROR( VALUE(REGEXREPLACE(TRIM(SPLIT(REGEXREPLACE(C24, ""[\[\]]"", """"), "","")), ""[^0-9.]"", """")), 0 ) ) ) )"),14000.0) -> 14000 | Q24: =IF(M24=0, 0, P24/M24) -> 2333.3333
A25: ID_R1I9PKB | B25: ['01-2018', '03-2018', '05-2018', '06-2018', '07-2018', '09-2018', '10-2018'] | C25: [9044.0, 6000.0, 6000.0, 3000.0, 3000.0, 3000.0, 6000.0] | D25: 5000 | E25: 5920 | F25: 1950 | G25: 2000 | H25: 3650 | I25: 2400 | J25: =SUM(D25:I25) -> 20920 | K25: =IFS( J25 <= 2000, "Low (<=2,000$ – Bottom ~25%)", J25 <= 4750, "Medium-Low (2,001–4,750$)", J25 <= 6630, "Medium-High (4,751–6,630$ – Top 50–75%)", TRUE, "High (>6,630$ – Top ~25%)" ) -> High (>6,630$ – Top ~25%) | L25: =IF(J25=0, "Default / High Risk", "Paid Something") -> Paid Something | M25: =IF(C25="", 0, LEN(C25) - LEN(SUBSTITUTE(C25, ",", "")) + 1) -> 7 | N25: =IFERROR(__xludf.DUMMYFUNCTION("IF(C25="""", 0, SUM(ARRAYFORMULA(IF(SPLIT(C25, "","")=""0"", 1, 0))))"),0.0) -> 0 | O25: =IF(C25="", "No History", IF(ISNUMBER(SEARCH(",0.0,", ","&C25&",")) + ISNUMBER(SEARCH(",0.0]", ","&C25&"]")) > 0, "Yes", "No")) -> No | P25: =IFERROR(__xludf.DUMMYFUNCTION("IF(C25="""", 0, SUM( ARRAYFORMULA( IFERROR( VALUE(REGEXREPLACE(TRIM(SPLIT(REGEXREPLACE(C25, ""[\[\]]"", """"), "","")), ""[^0-9.]"", """")), 0 ) ) ) )"),36044.0) -> 36044 | Q25: =IF(M25=0, 0, P25/M25) -> 5149.1429
A26: ID_VHVF5JN | B26: ['08-2017', '09-2017', '10-2017', '12-2017', '01-2018', '02-2018', '03-2018', '04-2018', '05-2018', '06-2018'] | C26: [2200.0, 1000.0, 200.0, 100.0, 40.0, 280.0, 500.0, 40.0, 500.0, 190.0] | D26: 5000 | E26: 40 | F26: 2000 | G26: 500 | H26: 1500 | I26: 2470 | J26: =SUM(D26:I26) -> 11510 | K26: =IFS( J26 <= 2000, "Low (<=2,000$ – Bottom ~25%)", J26 <= 4750, "Medium-Low (2,001–4,750$)", J26 <= 6630, "Medium-High (4,751–6,630$ – Top 50–75%)", TRUE, "High (>6,630$ – Top ~25%)" ) -> High (>6,630$ – Top ~25%) | L26: =IF(J26=0, "Default / High Risk", "Paid Something") -> Paid Something | M26: =IF(C26="", 0, LEN(C26) - LEN(SUBSTITUTE(C26, ",", "")) + 1) -> 10 | N26: =IFERROR(__xludf.DUMMYFUNCTION("IF(C26="""", 0, SUM(ARRAYFORMULA(IF(SPLIT(C26, "","")=""0"", 1, 0))))"),0.0) -> 0 | O26: =IF(C26="", "No History", IF(ISNUMBER(SEARCH(",0.0,", ","&C26&",")) + ISNUMBER(SEARCH(",0.0]", ","&C26&"]")) > 0, "Yes", "No")) -> No | P26: =IFERROR(__xludf.DUMMYFUNCTION("IF(C26="""", 0, SUM( ARRAYFORMULA( IFERROR( VALUE(REGEXREPLACE(TRIM(SPLIT(REGEXREPLACE(C26, ""[\[\]]"", """"), "","")), ""[^0-9.]"", """")), 0 ) ) ) )"),5050.0) -> 5050 | Q26: =IF(M26=0, 0, P26/M26) -> 505
A27: ID_B6G5XWG | B27: ['03-2018', '04-2018', '05-2018', '06-2018', '07-2018', '09-2018', '10-2018', '11-2018', '12-2018', '01-2019', '02-2019', '03-2019', '04-2019', '05-2019', '06-2019'] | C27: [4385.0, 2000.0, 1740.0, 915.0, 750.0, 100.0, 100.0, 100.0, 90.0, 200.0, 100.0, 200.0, 1300.0, 500.0, 5000.0] | D27: 5000 | E27: 4055 | F27: 1500 | G27: 2610 | H27: 2000 | I27: 604 | J27: =SUM(D27:I27) -> 15769 | K27: =IFS( J27 <= 2000, "Low (<=2,000$ – Bottom ~25%)", J27 <= 4750, "Medium-Low (2,001–4,750$)", J27 <= 6630, "Medium-High (4,751–6,630$ – Top 50–75%)", TRUE, "High (>6,630$ – Top ~25%)" ) -> High (>6,630$ – Top ~25%) | L27: =IF(J27=0, "Default / High Risk", "Paid Something") -> Paid Something | M27: =IF(C27="", 0, LEN(C27) - LEN(SUBSTITUTE(C27, ",", "")) + 1) -> 15 | N27: =IFERROR(__xludf.DUMMYFUNCTION("IF(C27="""", 0, SUM(ARRAYFORMULA(IF(SPLIT(C27, "","")=""0"", 1, 0))))"),0.0) -> 0 | O27: =IF(C27="", "No History", IF(ISNUMBER(SEARCH(",0.0,", ","&C27&",")) + ISNUMBER(SEARCH(",0.0]", ","&C27&"]")) > 0, "Yes", "No")) -> No | P27: =IFERROR(__xludf.DUMMYFUNCTION("IF(C27="""", 0, SUM( ARRAYFORMULA( IFERROR( VALUE(REGEXREPLACE(TRIM(SPLIT(REGEXREPLACE(C27, ""[\[\]]"", """"), "","")), ""[^0-9.]"", """")), 0 ) ) ) )"),17480.0) -> 17480 | Q27: =IF(M27=0, 0, P27/M27) -> 1165.3333
A28: ID_57M907H | B28: ['02-2018', '03-2018', '04-2018', '06-2018', '07-2018', '08-2018', '09-2018', '10-2018', '11-2018', '12-2018', '01-2019', '02-2019', '03-2019'] | C28: [6500.0, 3000.0, 5500.0, 3000.0, 2000.0, 1850.0, 2900.0, 3300.0, 3000.0, 2300.0, 2750.0, 2400.0, 2850.0] | D28: 4950 | E28: 1620 | F28: 2000 | G28: 2600 | H28: 2800 | I28: 1644 | J28: =SUM(D28:I28) -> 15614 | K28: =IFS( J28 <= 2000, "Low (<=2,000$ – Bottom ~25%)", J28 <= 4750, "Medium-Low (2,001–4,750$)", J28 <= 6630, "Medium-High (4,751–6,630$ – Top 50–75%)", TRUE, "High (>6,630$ – Top ~25%)" ) -> High (>6,630$ – Top ~25%) | L28: =IF(J28=0, "Default / High Risk", "Paid Something") -> Paid Something | M28: =IF(C28="", 0, LEN(C28) - LEN(SUBSTITUTE(C28, ",", "")) + 1) -> 13 | N28: =IFERROR(__xludf.DUMMYFUNCTION("IF(C28="""", 0, SUM(ARRAYFORMULA(IF(SPLIT(C28, "","")=""0"", 1, 0))))"),0.0) -> 0 | O28: =IF(C28="", "No History", IF(ISNUMBER(SEARCH(",0.0,", ","&C28&",")) + ISNUMBER(SEARCH(",0.0]", ","&C28&"]")) > 0, "Yes", "No")) -> No | P28: =IFERROR(__xludf.DUMMYFUNCTION("IF(C28="""", 0, SUM( ARRAYFORMULA( IFERROR( VALUE(REGEXREPLACE(TRIM(SPLIT(REGEXREPLACE(C28, ""[\[\]]"", """"), "","")), ""[^0-9.]"", """")), 0 ) ) ) )"),41350.0) -> 41350 | Q28: =IF(M28=0, 0, P28/M28) -> 3180.7692
A29: ID_LSS3OI1 | B29: ['04-2018', '05-2018', '07-2018', '08-2018', '09-2018', '10-2018', '11-2018', '12-2018', '01-2019', '02-2019', '03-2019'] | C29: [10490.0, 2090.0, 3840.0, 1260.0, 3900.0, 1610.0, 6475.0, 845.0, 2376.0, 3270.0, 1808.0] | D29: 4890 | E29: 1643 | F29: 4290 | G29: 4307 | H29: 1920 | I29: 1950 | J29: =SUM(D29:I29) -> 19000 | K29: =IFS( J29 <= 2000, "Low (<=2,000$ – Bottom ~25%)", J29 <= 4750, "Medium-Low (2,001–4,750$)", J29 <= 6630, "Medium-High (4,751–6,630$ – Top 50–75%)", TRUE, "High (>6,630$ – Top ~25%)" ) -> High (>6,630$ – Top ~25%) | L29: =IF(J29=0, "Default / High Risk", "Paid Something") -> Paid Something | M29: =IF(C29="", 0, LEN(C29) - LEN(SUBSTITUTE(C29, ",", "")) + 1) -> 11 | N29: =IFERROR(__xludf.DUMMYFUNCTION("IF(C29="""", 0, SUM(ARRAYFORMULA(IF(SPLIT(C29, "","")=""0"", 1, 0))))"),0.0) -> 0 | O29: =IF(C29="", "No History", IF(ISNUMBER(SEARCH(",0.0,", ","&C29&",")) + ISNUMBER(SEARCH(",0.0]", ","&C29&"]")) > 0, "Yes", "No")) -> No | P29: =IFERROR(__xludf.DUMMYFUNCTION("IF(C29="""", 0, SUM( ARRAYFORMULA( IFERROR( VALUE(REGEXREPLACE(TRIM(SPLIT(REGEXREPLACE(C29, ""[\[\]]"", """"), "","")), ""[^0-9.]"", """")), 0 ) ) ) )"),37964.0) -> 37964 | Q29: =IF(M29=0, 0, P29/M29) -> 3451.2727
A30: ID_JXHJ6FN | B30: ['01-2018', '02-2018', '03-2018', '04-2018', '07-2018', '08-2018', '09-2018', '10-2018', '11-2018', '01-2019', '02-2019'] | C30: [13000.0, 200.0, 1200.0, 1100.0, 2900.0, 1600.0, 2900.0, 5300.0, 3400.0, 3060.0, 4100.0] | D30: 4800 | E30: 3400 | F30: 1820 | G30: 2384 | H30: 4950 | I30: 850 | J30: =SUM(D30:I30) -> 18204 | K30: =IFS( J30 <= 2000, "Low (<=2,000$ – Bottom ~25%)", J30 <= 4750, "Medium-Low (2,001–4,750$)", J30 <= 6630, "Medium-High (4,751–6,630$ – Top 50–75%)", TRUE, "High (>6,630$ – Top ~25%)" ) -> High (>6,630$ – Top ~25%) | L30: =IF(J30=0, "Default / High Risk", "Paid Something") -> Paid Something | M30: =IF(C30="", 0, LEN(C30) - LEN(SUBSTITUTE(C30, ",", "")) + 1) -> 11 | N30: =IFERROR(__xludf.DUMMYFUNCTION("IF(C30="""", 0, SUM(ARRAYFORMULA(IF(SPLIT(C30, "","")=""0"", 1, 0))))"),0.0) -> 0 | O30: =IF(C30="", "No History", IF(ISNUMBER(SEARCH(",0.0,", ","&C30&",")) + ISNUMBER(SEARCH(",0.0]", ","&C30&"]")) > 0, "Yes", "No")) -> No | P30: =IFERROR(__xludf.DUMMYFUNCTION("IF(C30="""", 0, SUM( ARRAYFORMULA( IFERROR( VALUE(REGEXREPLACE(TRIM(SPLIT(REGEXREPLACE(C30, ""[\[\]]"", """"), "","")), ""[^0-9.]"", """")), 0 ) ) ) )"),38760.0) -> 38760 | Q30: =IF(M30=0, 0, P30/M30) -> 3523.6364
A31: ID_KGLRUBH | B31: ['01-2018', '02-2018', '03-2018', '04-2018', '05-2018', '06-2018', '07-2018', '09-2018', '12-2018', '01-2019'] | C31: [3000.0, 1340.0, 1700.0, 900.0, 2000.0, 1000.0, 2000.0, 5000.0, 500.0, 2000.0] | D31: 4700 | E31: 110 | F31: 2150 | G31: 1650 | H31: 3810 | I31: 1334 | J31: =SUM(D31:I31) -> 13754 | K31: =IFS( J31 <= 2000, "Low (<=2,000$ – Bottom ~25%)", J31 <= 4750, "Medium-Low (2,001–4,750$)", J31 <= 6630, "Medium-High (4,751–6,630$ – Top 50–75%)", TRUE, "High (>6,630$ – Top ~25%)" ) -> High (>6,630$ – Top ~25%) | L31: =IF(J31=0, "Default / High Risk", "Paid Something") -> Paid Something | M31: =IF(C31="", 0, LEN(C31) - LEN(SUBSTITUTE(C31, ",", "")) + 1) -> 10 | N31: =IFERROR(__xludf.DUMMYFUNCTION("IF(C31="""", 0, SUM(ARRAYFORMULA(IF(SPLIT(C31, "","")=""0"", 1, 0))))"),0.0) -> 0 | O31: =IF(C31="", "No History", IF(ISNUMBER(SEARCH(",0.0,", ","&C31&",")) + ISNUMBER(SEARCH(",0.0]", ","&C31&"]")) > 0, "Yes", "No")) -> No | P31: =IFERROR(__xludf.DUMMYFUNCTION("IF(C31="""", 0, SUM( ARRAYFORMULA( IFERROR( VALUE(REGEXREPLACE(TRIM(SPLIT(REGEXREPLACE(C31, ""[\[\]]"", """"), "","")), ""[^0-9.]"", """")), 0 ) ) ) )"),19440.0) -> 19440 | Q31: =IF(M31=0, 0, P31/M31) -> 1944
A32: ID_42ZPUHQ | B32: ['07-2017', '08-2017', '09-2017', '10-2017', '11-2017', '01-2018', '03-2018', '04-2018', '05-2018', '06-2018', '07-2018', '08-2018', '09-2018', '10-2018', '11-2018', '12-2018', '01-2019', '02-2019', '03-2019', '04-2019', '05-2019', '06-2019', '07-2019', '08-2019', '09-2019', '10-2019', '11-2019', '12-2019', '01-2020', '02-2020', '03-2020', '07-2020'] | C32: [2300.0, 880.0, 1140.0, 580.0, 80.0, 160.0, 280.0, 80.0, 40.0, 120.0, 40.0, 80.0, 80.0, 80.0, 100.0, 120.0, 120.0, 80.0, 80.0, 50.0, 80.0, 220.0, 480.0, 240.0, 10.0, 200.0, 80.0, 80.0, 80.0, 40.0, 80.0, 40.0] | D32: 4680 | E32: 1580 | F32: 180 | G32: 280 | H32: 160 | I32: 120 | J32: =SUM(D32:I32) -> 7000 | K32: =IFS( J32 <= 2000, "Low (<=2,000$ – Bottom ~25%)", J32 <= 4750, "Medium-Low (2,001–4,750$)", J32 <= 6630, "Medium-High (4,751–6,630$ – Top 50–75%)", TRUE, "High (>6,630$ – Top ~25%)" ) -> High (>6,630$ – Top ~25%) | L32: =IF(J32=0, "Default / High Risk", "Paid Something") -> Paid Something | M32: =IF(C32="", 0, LEN(C32) - LEN(SUBSTITUTE(C32, ",", "")) + 1) -> 32 | N32: =IFERROR(__xludf.DUMMYFUNCTION("IF(C32="""", 0, SUM(ARRAYFORMULA(IF(SPLIT(C32, "","")=""0"", 1, 0))))"),0.0) -> 0 | O32: =IF(C32="", "No History", IF(ISNUMBER(SEARCH(",0.0,", ","&C32&",")) + ISNUMBER(SEARCH(",0.0]", ","&C32&"]")) > 0, "Yes", "No")) -> No | P32: =IFERROR(__xludf.DUMMYFUNCTION("IF(C32="""", 0, SUM( ARRAYFORMULA( IFERROR( VALUE(REGEXREPLACE(TRIM(SPLIT(REGEXREPLACE(C32, ""[\[\]]"", """"), "","")), ""[^0-9.]"", """")), 0 ) ) ) )"),8120.0) -> 8120 | Q32: =IF(M32=0, 0, P32/M32) -> 253.75
A33: ID_MD6DS1G | B33: ['01-2020', '02-2020', '03-2020', '04-2020', '05-2020'] | C33: [2300.0, 1360.0, 880.0, 1080.0, 1089.0] | D33: 4530 | E33: 50 | F33: 50 | G33: 70 | H33: 1262 | I33: 130 | J33: =SUM(D33:I33) -> 6092 | K33: =IFS( J33 <= 2000, "Low (<=2,000$ – Bottom ~25%)", J33 <= 4750, "Medium-Low (2,001–4,750$)", J33 <= 6630, "Medium-High (4,751–6,630$ – Top 50–75%)", TRUE, "High (>6,630$ – Top ~25%)" ) -> Medium-High (4,751–6,630$ – Top 50–75%) | L33: =IF(J33=0, "Default / High Risk", "Paid Something") -> Paid Something | M33: =IF(C33="", 0, LEN(C33) - LEN(SUBSTITUTE(C33, ",", "")) + 1) -> 5 | N33: =IFERROR(__xludf.DUMMYFUNCTION("IF(C33="""", 0, SUM(ARRAYFORMULA(IF(SPLIT(C33, "","")=""0"", 1, 0))))"),0.0) -> 0 | O33: =IF(C33="", "No History", IF(ISNUMBER(SEARCH(",0.0,", ","&C33&",")) + ISNUMBER(SEARCH(",0.0]", ","&C33&"]")) > 0, "Yes", "No")) -> No | P33: =IFERROR(__xludf.DUMMYFUNCTION("IF(C33="""", 0, SUM( ARRAYFORMULA( IFERROR( VALUE(REGEXREPLACE(TRIM(SPLIT(REGEXREPLACE(C33, ""[\[\]]"", """"), "","")), ""[^0-9.]"", """")), 0 ) ) ) )"),6709.0) -> 6709 | Q33: =IF(M33=0, 0, P33/M33) -> 1341.8
A34: ID_TTHZCZN | B34: ['03-2018', '04-2018', '05-2018', '06-2018', '07-2018', '09-2018', '11-2018', '12-2018', '02-2019', '03-2019', '04-2019', '05-2019'] | C34: [2500.0, 2700.0, 1150.0, 2000.0, 1900.0, 2400.0, 1650.0, 2000.0, 2000.0, 2000.0, 1000.0, 1500.0] | D34: 4500 | E34: 700 | F34: 1500 | G34: 1000 | H34: 2220 | I34: 825 | J34: =SUM(D34:I34) -> 10745 | K34: =IFS( J34 <= 2000, "Low (<=2,000$ – Bottom ~25%)", J34 <= 4750, "Medium-Low (2,001–4,750$)", J34 <= 6630, "Medium-High (4,751–6,630$ – Top 50–75%)", TRUE, "High (>6,630$ – Top ~25%)" ) -> High (>6,630$ – Top ~25%) | L34: =IF(J34=0, "Default / High Risk", "Paid Something") -> Paid Something | M34: =IF(C34="", 0, LEN(C34) - LEN(SUBSTITUTE(C34, ",", "")) + 1) -> 12 | N34: =IFERROR(__xludf.DUMMYFUNCTION("IF(C34="""", 0, SUM(ARRAYFORMULA(IF(SPLIT(C34, "","")=""0"", 1, 0))))"),0.0) -> 0 | O34: =IF(C34="", "No History", IF(ISNUMBER(SEARCH(",0.0,", ","&C34&",")) + ISNUMBER(SEARCH(",0.0]", ","&C34&"]")) > 0, "Yes", "No")) -> No | P34: =IFERROR(__xludf.DUMMYFUNCTION("IF(C34="""", 0, SUM( ARRAYFORMULA( IFERROR( VALUE(REGEXREPLACE(TRIM(SPLIT(REGEXREPLACE(C34, ""[\[\]]"", """"), "","")), ""[^0-9.]"", """")), 0 ) ) ) )"),22800.0) -> 22800 | Q34: =IF(M34=0, 0, P34/M34) -> 1900
A35: ID_RMBBUQ8 | B35: ['04-2018', '05-2018', '06-2018', '09-2018', '12-2018'] | C35: [3275.0, 3500.0, 6000.0, 5000.0, 3000.0] | D35: 4500 | E35: 1650 | F35: 1900 | G35: 650 | H35: 2000 | I35: 1605 | J35: =SUM(D35:I35) -> 12305 | K35: =IFS( J35 <= 2000, "Low (<=2,000$ – Bottom ~25%)", J35 <= 4750, "Medium-Low (2,001–4,750$)", J35 <= 6630, "Medium-High (4,751–6,630$ – Top 50–75%)", TRUE, "High (>6,630$ – Top ~25%)" ) -> High (>6,630$ – Top ~25%) | L35: =IF(J35=0, "Default / High Risk", "Paid Something") -> Paid Something | M35: =IF(C35="", 0, LEN(C35) - LEN(SUBSTITUTE(C35, ",", "")) + 1) -> 5 | N35: =IFERROR(__xludf.DUMMYFUNCTION("IF(C35="""", 0, SUM(ARRAYFORMULA(IF(SPLIT(C35, "","")=""0"", 1, 0))))"),0.0) -> 0 | O35: =IF(C35="", "No History", IF(ISNUMBER(SEARCH(",0.0,", ","&C35&",")) + ISNUMBER(SEARCH(",0.0]", ","&C35&"]")) > 0, "Yes", "No")) -> No | P35: =IFERROR(__xludf.DUMMYFUNCTION("IF(C35="""", 0, SUM( ARRAYFORMULA( IFERROR( VALUE(REGEXREPLACE(TRIM(SPLIT(REGEXREPLACE(C35, ""[\[\]]"", """"), "","")), ""[^0-9.]"", """")), 0 ) ) ) )"),20775.0) -> 20775 | Q35: =IF(M35=0, 0, P35/M35) -> 4155
A36: ID_1K1SQNA | B36: ['04-2018', '05-2018', '06-2018', '08-2018', '09-2018'] | C36: [4000.0, 4000.0, 2000.0, 1000.0, 2500.0] | D36: 4500 | E36: 1500 | F36: 3900 | G36: 2000 | H36: 5680 | I36: 2000 | J36: =SUM(D36:I36) -> 19580 | K36: =IFS( J36 <= 2000, "Low (<=2,000$ – Bottom ~25%)", J36 <= 4750, "Medium-Low (2,001–4,750$)", J36 <= 6630, "Medium-High (4,751–6,630$ – Top 50–75%)", TRUE, "High (>6,630$ – Top ~25%)" ) -> High (>6,630$ – Top ~25%) | L36: =IF(J36=0, "Default / High Risk", "Paid Something") -> Paid Something | M36: =IF(C36="", 0, LEN(C36) - LEN(SUBSTITUTE(C36, ",", "")) + 1) -> 5 | N36: =IFERROR(__xludf.DUMMYFUNCTION("IF(C36="""", 0, SUM(ARRAYFORMULA(IF(SPLIT(C36, "","")=""0"", 1, 0))))"),0.0) -> 0 | O36: =IF(C36="", "No History", IF(ISNUMBER(SEARCH(",0.0,", ","&C36&",")) + ISNUMBER(SEARCH(",0.0]", ","&C36&"]")) > 0, "Yes", "No")) -> No | P36: =IFERROR(__xludf.DUMMYFUNCTION("IF(C36="""", 0, SUM( ARRAYFORMULA( IFERROR( VALUE(REGEXREPLACE(TRIM(SPLIT(REGEXREPLACE(C36, ""[\[\]]"", """"), "","")), ""[^0-9.]"", """")), 0 ) ) ) )"),13500.0) -> 13500 | Q36: =IF(M36=0, 0, P36/M36) -> 2700
A37: ID_I0HHIJY | B37: ['02-2018', '03-2018', '04-2018', '05-2018', '06-2018', '08-2018', '09-2018', '10-2018', '11-2018', '12-2018', '01-2019', '02-2019', '03-2019', '04-2019', '05-2019', '06-2019', '07-2019', '08-2019', '09-2019', '10-2019', '11-2019', '12-2019'] | C37: [3000.0, 1600.0, 1200.0, 800.0, 620.0, 220.0, 275.0, 1200.0, 1200.0, 165.0, 400.0, 330.0, 400.0, 660.0, 165.0, 730.0, 1130.0, 495.0, 1420.0, 1410.0, 2200.0, 55.0] | D37: 4410 | E37: 4200 | F37: 2000 | G37: 550 | H37: 510 | I37: 1740 | J37: =SUM(D37:I37) -> 13410 | K37: =IFS( J37 <= 2000, "Low (<=2,000$ – Bottom ~25%)", J37 <= 4750, "Medium-Low (2,001–4,750$)", J37 <= 6630, "Medium-High (4,751–6,630$ – Top 50–75%)", TRUE, "High (>6,630$ – Top ~25%)" ) -> High (>6,630$ – Top ~25%) | L37: =IF(J37=0, "Default / High Risk", "Paid Something") -> Paid Something | M37: =IF(C37="", 0, LEN(C37) - LEN(SUBSTITUTE(C37, ",", "")) + 1) -> 22 | N37: =IFERROR(__xludf.DUMMYFUNCTION("IF(C37="""", 0, SUM(ARRAYFORMULA(IF(SPLIT(C37, "","")=""0"", 1, 0))))"),0.0) -> 0 | O37: =IF(C37="", "No History", IF(ISNUMBER(SEARCH(",0.0,", ","&C37&",")) + ISNUMBER(SEARCH(",0.0]", ","&C37&"]")) > 0, "Yes", "No")) -> No | P37: =IFERROR(__xludf.DUMMYFUNCTION("IF(C37="""", 0, SUM( ARRAYFORMULA( IFERROR( VALUE(REGEXREPLACE(TRIM(SPLIT(REGEXREPLACE(C37, ""[\[\]]"", """"), "","")), ""[^0-9.]"", """")), 0 ) ) ) )"),19675.0) -> 19675 | Q37: =IF(M37=0, 0, P37/M37) -> 894.31818
A38: ID_SBG9SEF | B38: ['04-2018', '05-2018', '06-2018', '07-2018', '08-2018', '09-2018', '10-2018', '11-2018', '12-2018', '01-2019', '02-2019', '03-2019', '04-2019', '05-2019', '06-2019', '07-2019', '08-2019', '09-2019'] | C38: [9640.0, 955.0, 1550.0, 2300.0, 2495.0, 2755.0, 1860.0, 2350.0, 1945.0, 2280.0, 2158.0, 2390.0, 2535.0, 2292.0, 2447.0, 2820.0, 2590.0, 2370.0] | D38: 4400 | E38: 1500 | F38: 2270 | G38: 1062 | H38: 95 | I38: 245 | J38: =SUM(D38:I38) -> 9572 | K38: =IFS( J38 <= 2000, "Low (<=2,000$ – Bottom ~25%)", J38 <= 4750, "Medium-Low (2,001–4,750$)", J38 <= 6630, "Medium-High (4,751–6,630$ – Top 50–75%)", TRUE, "High (>6,630$ – Top ~25%)" ) -> High (>6,630$ – Top ~25%) | L38: =IF(J38=0, "Default / High Risk", "Paid Something") -> Paid Something | M38: =IF(C38="", 0, LEN(C38) - LEN(SUBSTITUTE(C38, ",", "")) + 1) -> 18 | N38: =IFERROR(__xludf.DUMMYFUNCTION("IF(C38="""", 0, SUM(ARRAYFORMULA(IF(SPLIT(C38, "","")=""0"", 1, 0))))"),0.0) -> 0 | O38: =IF(C38="", "No History", IF(ISNUMBER(SEARCH(",0.0,", ","&C38&",")) + ISNUMBER(SEARCH(",0.0]", ","&C38&"]")) > 0, "Yes", "No")) -> No | P38: =IFERROR(__xludf.DUMMYFUNCTION("IF(C38="""", 0, SUM( ARRAYFORMULA( IFERROR( VALUE(REGEXREPLACE(TRIM(SPLIT(REGEXREPLACE(C38, ""[\[\]]"", """"), "","")), ""[^0-9.]"", """")), 0 ) ) ) )"),47732.0) -> 47732 | Q38: =IF(M38=0, 0, P38/M38) -> 2651.7778
A39: ID_8YT8ULM | B39: ['03-2018', '04-2018', '05-2018', '06-2018', '07-2018', '08-2018', '09-2018', '10-2018', '11-2018', '12-2018', '01-2019'] | C39: [3050.0, 1705.0, 1045.0, 1705.0, 1760.0, 1966.0, 2750.0, 660.0, 2365.0, 1650.0, 2200.0] | D39: 4400 | E39: 2200 | F39: 2200 | G39: 1155 | H39: 2270 | I39: 219 | J39: =SUM(D39:I39) -> 12444 | K39: =IFS( J39 <= 2000, "Low (<=2,000$ – Bottom ~25%)", J39 <= 4750, "Medium-Low (2,001–4,750$)", J39 <= 6630, "Medium-High (4,751–6,630$ – Top 50–75%)", TRUE, "High (>6,630$ – Top ~25%)" ) -> High (>6,630$ – Top ~25%) | L39: =IF(J39=0, "Default / High Risk", "Paid Something") -> Paid Something | M39: =IF(C39="", 0, LEN(C39) - LEN(SUBSTITUTE(C39, ",", "")) + 1) -> 11 | N39: =IFERROR(__xludf.DUMMYFUNCTION("IF(C39="""", 0, SUM(ARRAYFORMULA(IF(SPLIT(C39, "","")=""0"", 1, 0))))"),0.0) -> 0 | O39: =IF(C39="", "No History", IF(ISNUMBER(SEARCH(",0.0,", ","&C39&",")) + ISNUMBER(SEARCH(",0.0]", ","&C39&"]")) > 0, "Yes", "No")) -> No | P39: =IFERROR(__xludf.DUMMYFUNCTION("IF(C39="""", 0, SUM( ARRAYFORMULA( IFERROR( VALUE(REGEXREPLACE(TRIM(SPLIT(REGEXREPLACE(C39, ""[\[\]]"", """"), "","")), ""[^0-9.]"", """")), 0 ) ) ) )"),20856.0) -> 20856 | Q39: =IF(M39=0, 0, P39/M39) -> 1896
A40: ID_LXXEIN9 | B40: ['04-2018', '08-2018', '10-2018', '11-2018', '12-2018', '01-2019', '02-2019', '03-2019', '04-2019', '05-2019', '06-2019', '07-2019'] | C40: [13000.0, 3000.0, 3000.0, 3000.0, 2000.0, 4000.0, 1000.0, 3300.0, 2000.0, 3600.0, 2100.0, 2500.0] | D40: 4305 | E40: 3000 | F40: 3110 | G40: 2100 | H40: 2385 | I40: 700 | J40: =SUM(D40:I40) -> 15600 | K40: =IFS( J40 <= 2000, "Low (<=2,000$ – Bottom ~25%)", J40 <= 4750, "Medium-Low (2,001–4,750$)", J40 <= 6630, "Medium-High (4,751–6,630$ – Top 50–75%)", TRUE, "High (>6,630$ – Top ~25%)" ) -> High (>6,630$ – Top ~25%) | L40: =IF(J40=0, "Default / High Risk", "Paid Something") -> Paid Something | M40: =IF(C40="", 0, LEN(C40) - LEN(SUBSTITUTE(C40, ",", "")) + 1) -> 12 | N40: =IFERROR(__xludf.DUMMYFUNCTION("IF(C40="""", 0, SUM(ARRAYFORMULA(IF(SPLIT(C40, "","")=""0"", 1, 0))))"),0.0) -> 0 | O40: =IF(C40="", "No History", IF(ISNUMBER(SEARCH(",0.0,", ","&C40&",")) + ISNUMBER(SEARCH(",0.0]", ","&C40&"]")) > 0, "Yes", "No")) -> No | P40: =IFERROR(__xludf.DUMMYFUNCTION("IF(C40="""", 0, SUM( ARRAYFORMULA( IFERROR( VALUE(REGEXREPLACE(TRIM(SPLIT(REGEXREPLACE(C40, ""[\[\]]"", """"), "","")), ""[^0-9.]"", """")), 0 ) ) ) )"),42500.0) -> 42500 | Q40: =IF(M40=0, 0, P40/M40) -> 3541.6667
...

Sheet Summary & Insights
A1: Metric/ Insight | B1: Value | C1: Notes/Interpretation | J1: =MIN(J2:J28008) -> 0
A2: Correlation: Past Total Paid → Future Repaid | B2: =CORREL(Cleaned_Working!P:P, Cleaned_Working!J:J) -> 0.18917404 | C2: Customers who paid more historically tend to repay more in the future, but it’s not extremely strong
A3: Correlation: Past Avg Payment → Future Repaid | B3: =CORREL(Cleaned_Working!Q:Q, Cleaned_Working!J:J) -> 0.38579715 | C3: Average historical payment size is a much better predictor of future repayment strength than total past paid alone.
A4: Avg Future Repaid (High Bucket) | B4: =AVERAGEIF(Cleaned_Working!K:K, "*High*", Cleaned_Working!J:J) -> 16125.561 | C4: Top ~25% repayers paid ~7.3k on average in next 6 months — solid cash flow contributors.
A5: Avg Future Repaid (Low Bucket) | B5: =AVERAGEIF(Cleaned_Working!K:K, "*Low*", Cleaned_Working!J:J) -> 4330 | C5: Bottom ~25% repayers paid only ~2.2k on average — ~3.3× less than High bucket → clear risk segment.
A6: Avg Past Avg Payment (High bucket) | B6: =AVERAGEIF(Cleaned_Working!K:K, "*High*", Cleaned_Working!Q:Q) -> 2475.8587 | C6: Top repayers had much larger average payments historically (~$1,367 per period).
A7: Avg Past Avg Payment (Low bucket) | B7: =AVERAGEIF(Cleaned_Working!K:K, "*Low*", Cleaned_Working!Q:Q) -> 1644 | C7: Bottom repayers had ~$774 avg per period — ~1.77× smaller than High bucket.
A8: % Customers in High bucket | B8: =COUNTIF(Cleaned_Working!K:K, "High (>6,630$ – Top ~25%)") / COUNTA(Cleaned_Working!K:K) -> 0.93 | C8: Roughly as designed.
A9: % Customers in Low bucket | B9: =COUNTIF(Cleaned_Working!K:K, "*Low*") / COUNTA(Cleaned_Working!K:K) -> 0.01 | C9: Slightly higher than expected
A10: Overall Avg Total Past Paid | B10: =AVERAGE(Cleaned_Working!P:P) -> 26341.384 | C10: Benchmark: average customer paid ~15k historically before snapshot.
A11: Overall Avg Past Avg Payment | B11: =AVERAGE(Cleaned_Working!Q:Q) -> 2467.4561 | C11: Benchmark: typical average payment per historical period ~$1,070.
A15: Strongest Insight: Past average payment size strongly predicts future repayment strength → actionable for customer segmentation and risk reduction.
